<?xml version="1.0"?>
<robot xmlns:xacro="http://www.ros.org/wiki/xacro" >

    <xacro:macro name="wheel" params="name parent_link wheel_distance wheel_radius wheel_length wheel_mass">

        <joint name="${name}_joint" type="continuous">
            <parent link="${parent_link}"/>
            <child link="${name}"/>
            <origin xyz="0 ${wheel_distance} 0" rpy="-${pi/2} 0 0"/>
            <axis xyz="0 0 1"/>
        </joint>

        <link name="${name}">
            <xacro:inertial_cylinder mass="${wheel_mass}" radius="${wheel_radius}" length="${wheel_length}">
                <origin xyz="0 0 0" rpy="0 0 0" />
            </xacro:inertial_cylinder>
            
            <visual>
                <geometry>
                    <cylinder radius="${wheel_radius}" length="${wheel_length}"/>
                </geometry>
                <material name="blue"/>
            </visual>
            
            <collision>
                <geometry>
                    <cylinder radius="${wheel_radius}" length="${wheel_length}"/>
                </geometry>
            </collision>
        </link>
        
    </xacro:macro>

</robot>