<?xml version="1.0" ?>
<!-- =================================================================================== -->
<!-- |    This document was autogenerated by xacro from src/igvc/description/ackermann_ac.urdf | -->
<!-- |    EDITING THIS FILE BY HAND IS NOT RECOMMENDED                                 | -->
<!-- =================================================================================== -->
<robot name="igvc25">
  <material name="white">
    <color rgba="1 1 1 0.1"/>
  </material>
  <material name="black">
    <color rgba="0 0 0 1"/>
  </material>
  <material name="red">
    <color rgba="1 0 0 1"/>
  </material>
  <material name="green">
    <color rgba="0 1 0 1"/>
  </material>
  <material name="blue">
    <color rgba="0.2 0.2 1 1"/>
  </material>
  <material name="orange">
    <color rgba="1 0.3 0.1 1"/>
  </material>
  <!-- Specify some standard inertial calculations https://en.wikipedia.org/wiki/List_of_moments_of_inertia -->
  <!-- These make use of xacro's mathematical functionality -->
  <!--
        MARK: steer
    -->
  <!--
        MARK: flat-lidar
    -->
  <!--
        MARK: imu
    -->
  <!--
        MARK: GPS
    -->
  <!--
        MARK: Camera
    -->
  <link name="base_link"/>
  <joint name="front_left_steering_joint" type="continuous">
    <parent link="base_link"/>
    <child link="front_left_steering_knuckle"/>
    <origin xyz="0 0.3 0"/>
    <axis xyz="0 0 1"/>
  </joint>
  <link name="front_left_steering_knuckle">
    <!-- <xacro:inertial_box mass="0.1" x="0.01" y="0.01" z="0.1">
        <origin xyz="0 0 0" />
      </xacro:inertial_box> -->
  </link>
  <joint name="front_left_wheel_mount" type="fixed">
    <parent link="front_left_steering_knuckle"/>
    <child link="front_left_wheel"/>
    <origin rpy="-1.5707963267948966 0 0" xyz="0 0.1 0"/>
  </joint>
  <link name="front_left_wheel">
    <inertial>
      <origin xyz="0 0 0"/>
      <mass value="1.0"/>
      <inertia ixx="0.00629031" ixy="0.0" ixz="0.0" iyy="0.00629031" iyz="0.0" izz="0.01161288"/>
    </inertial>
    <visual>
      <geometry>
        <cylinder length="0.0762" radius="0.1524"/>
      </geometry>
      <material name="blue"/>
    </visual>
    <collision>
      <geometry>
        <cylinder length="0.0762" radius="0.1524"/>
      </geometry>
    </collision>
  </link>
  <joint name="front_right_steering_joint" type="continuous">
    <parent link="base_link"/>
    <child link="front_right_steering_knuckle"/>
    <origin xyz="0 -0.3 0"/>
    <axis xyz="0 0 1"/>
  </joint>
  <link name="front_right_steering_knuckle">
    <!-- <xacro:inertial_box mass="0.1" x="0.01" y="0.01" z="0.1">
        <origin xyz="0 0 0" />
      </xacro:inertial_box> -->
  </link>
  <joint name="front_right_wheel_mount" type="fixed">
    <parent link="front_right_steering_knuckle"/>
    <child link="front_right_wheel"/>
    <origin rpy="-1.5707963267948966 0 0" xyz="0 -0.1 0"/>
  </joint>
  <link name="front_right_wheel">
    <inertial>
      <origin xyz="0 0 0"/>
      <mass value="1.0"/>
      <inertia ixx="0.00629031" ixy="0.0" ixz="0.0" iyy="0.00629031" iyz="0.0" izz="0.01161288"/>
    </inertial>
    <visual>
      <geometry>
        <cylinder length="0.0762" radius="0.1524"/>
      </geometry>
      <material name="blue"/>
    </visual>
    <collision>
      <geometry>
        <cylinder length="0.0762" radius="0.1524"/>
      </geometry>
    </collision>
  </link>
  <link name="pinion">
    <visual>
      <geometry>
        <cylinder length="0.025" radius="0.05"/>
      </geometry>
      <material name="black"/>
    </visual>
  </link>
  <joint name="pinion_joint" type="continuous">
    <parent link="base_link"/>
    <child link="pinion"/>
    <origin rpy="0.0 -1.5707963267948966 0.0" xyz="0.0 0.0 0.1"/>
    <axis xyz="0 0 1"/>
  </joint>
  <!-- MARK: DRIVE
  === BACK === -->
  <link name="diff_link"/>
  <joint name="diff_joint" type="fixed">
    <parent link="base_link"/>
    <child link="diff_link"/>
    <origin xyz="-0.9144 0 0"/>
  </joint>
  <joint name="back_left_wheel_joint" type="continuous">
    <parent link="diff_link"/>
    <child link="back_left_wheel"/>
    <origin rpy="-1.5707963267948966 0 0" xyz="0 0.3 0"/>
    <axis xyz="0 0 1"/>
  </joint>
  <link name="back_left_wheel">
    <inertial>
      <origin rpy="0 0 0" xyz="0 0 0"/>
      <mass value="1.0"/>
      <inertia ixx="0.00629031" ixy="0.0" ixz="0.0" iyy="0.00629031" iyz="0.0" izz="0.01161288"/>
    </inertial>
    <visual>
      <geometry>
        <cylinder length="0.0762" radius="0.1524"/>
      </geometry>
      <material name="blue"/>
    </visual>
    <collision>
      <geometry>
        <cylinder length="0.0762" radius="0.1524"/>
      </geometry>
    </collision>
  </link>
  <joint name="back_right_wheel_joint" type="continuous">
    <parent link="diff_link"/>
    <child link="back_right_wheel"/>
    <origin rpy="-1.5707963267948966 0 0" xyz="0 -0.3 0"/>
    <axis xyz="0 0 1"/>
  </joint>
  <link name="back_right_wheel">
    <inertial>
      <origin rpy="0 0 0" xyz="0 0 0"/>
      <mass value="1.0"/>
      <inertia ixx="0.00629031" ixy="0.0" ixz="0.0" iyy="0.00629031" iyz="0.0" izz="0.01161288"/>
    </inertial>
    <visual>
      <geometry>
        <cylinder length="0.0762" radius="0.1524"/>
      </geometry>
      <material name="blue"/>
    </visual>
    <collision>
      <geometry>
        <cylinder length="0.0762" radius="0.1524"/>
      </geometry>
    </collision>
  </link>
  <link name="motor">
    <visual>
      <geometry>
        <cylinder length="0.025" radius="0.05"/>
      </geometry>
      <material name="black"/>
    </visual>
  </link>
  <joint name="motor_joint" type="continuous">
    <parent link="diff_link"/>
    <child link="motor"/>
    <origin rpy="0.0 -1.5707963267948966 0.0" xyz="0.0 0.0 0.1"/>
    <axis xyz="0 0 1"/>
  </joint>
</robot>
